Workbook

Sheet Leads
A1: # | B1: Priority | C1: Lead type | D1: Business | E1: Category | F1: Region | G1: DM on | H1: Instagram | I1: Facebook | J1: Phone | K1: Website | L1: What we found | M1: Suggested first DM (fill the [bracket] first) | N1: Check on Google Maps | O1: Status | P1: Assigned to | Q1: Date contacted | R1: Follow-up date | S1: Notes
A2: 1 | B2: HIGH | C2: No own website | D2: Ferny Way Bakery | E2: bakery | F2: Brisbane | G2: Facebook | I2: https://www.facebook.com/Ferny-Way-Bakery-689190028097407/ | J2: +61 7 3351 2708 | K2: https://www.facebook.com/Ferny-Way-Bakery-689190028097407/ | L2: no real website (uses www.facebook.com) | M2: Hi Ferny Way Bakery team! [one real detail from their page]. We're AceAds, a web design studio. We noticed that when people in Brisbane search for a bakery on Google, they only find your Facebook, not a website of your own. We'd be happy to make you a free preview of what a website could look like. Want one? No cost, no obligation. | N2: Open map | O2: Not contacted
A3: 2 | B3: HIGH | C3: No own website | D3: Karana Krusty Bakery | E3: bakery | F3: Brisbane | G3: Facebook | I3: https://www.facebook.com/Bakery-Karana-Downs-624286981023430/ | J3: +61 7 3201 0104 | K3: https://www.facebook.com/Bakery-Karana-Downs-624286981023430/ | L3: no real website (uses www.facebook.com) | M3: Hi Karana Krusty Bakery team! [one real detail from their page]. We're AceAds, a web design studio. We noticed that when people in Brisbane search for a bakery on Google, they only find your Facebook, not a website of your own. We'd be happy to make you a free preview of what a website could look like. Want one? No cost, no obligation. | N3: Open map | O3: Not contacted
A4: 3 | B4: HIGH | C4: No own website | D4: Flat Lizard Brewing | E4: bar or pub | F4: Brisbane | G4: Facebook | I4: https://www.facebook.com/flatlizardbrewing/ | K4: https://www.facebook.com/flatlizardbrewing/ | L4: no real website (uses www.facebook.com) | M4: Hi Flat Lizard Brewing team! [one real detail from their page]. We're AceAds, a web design studio. We noticed that when people in Brisbane search for a bar on Google, they only find your Facebook, not a website of your own. We'd be happy to make you a free preview of what a website could look like. Want one? No cost, no obligation. | N4: Open map | O4: Not contacted
A5: 4 | B5: HIGH | C5: No own website | D5: Bella Vision Hair Studio | E5: barber or hairdresser | F5: Brisbane | G5: Facebook | I5: https://www.facebook.com/bellavisionhairstudio132 | J5: +61 7 3351 0200 | K5: https://www.facebook.com/bellavisionhairstudio132/ | L5: no real website (uses www.facebook.com) | M5: Hi Bella Vision Hair Studio team! [one real detail from their page]. We're AceAds, a web design studio. We noticed that when people in Brisbane search for a hairdresser on Google, they only find your Facebook, not a website of your own. We'd be happy to make you a free preview of what a website could look like. Want one? No cost, no obligation. | N5: Open map | O5: Not contacted
A6: 5 | B6: HIGH | C6: No own website | D6: Brass Knuckles Barber | E6: barber or hairdresser | F6: Brisbane | G6: Instagram | H6: https://www.instagram.com/brassknuckles_barber/ | J6: +61 493 369 135 | K6: https://www.instagram.com/brassknuckles_barber/ | L6: no real website (uses www.instagram.com) | M6: Hi Brass Knuckles Barber team! [one real detail from their page]. We're AceAds, a web design studio. We noticed that when people in Brisbane search for a hairdresser on Google, they only find your Instagram, not a website of your own. We'd be happy to make you a free preview of what a website could look like. Want one? No cost, no obligation. | N6: Open map | O6: Not contacted
A7: 6 | B7: HIGH | C7: No own website | D7: Crown and Co Barbers | E7: barber or hairdresser | F7: Brisbane | G7: Facebook | I7: https://www.facebook.com/crownandcobarbers/?ref=page_internal | K7: https://www.facebook.com/crownandcobarbers/?ref=page_internal | L7: no real website (uses www.facebook.com) | M7: Hi Crown and Co Barbers team! [one real detail from their page]. We're AceAds, a web design studio. We noticed that when people in Brisbane search for a hairdresser on Google, they only find your Facebook, not a website of your own. We'd be happy to make you a free preview of what a website could look like. Want one? No cost, no obligation. | N7: Open map | O7: Not contacted
A8: 7 | B8: HIGH | C8: No own website | D8: Kin Barbershop | E8: barber or hairdresser | F8: Brisbane | G8: Facebook | I8: https://www.facebook.com/p/Kin-Barbershop-61557611918699 | J8: +61 411 614 614 | K8: https://kinbarbershop.square.site/ | L8: no real website (uses kinbarbershop.square.site) | M8: Hi Kin Barbershop team! [one real detail from their page]. We're AceAds, a web design studio. We noticed that when people in Brisbane search for a hairdresser on Google, they only find your Facebook, not a website of your own. We'd be happy to make you a free preview of what a website could look like. Want one? No cost, no obligation. | N8: Open map | O8: Not contacted
A9: 8 | B9: HIGH | C9: No own website | D9: Scotty Barberino's Barber Shop | E9: barber or hairdresser | F9: Brisbane | G9: Facebook | I9: https://facebook.com/scottybarberinos/ | J9: +61 7 3289 2468 | K9: https://facebook.com/scottybarberinos/ | L9: no real website (uses facebook.com) | M9: Hi Scotty Barberino's Barber Shop team! [one real detail from their page]. We're AceAds, a web design studio. We noticed that when people in Brisbane search for a hairdresser on Google, they only find your Facebook, not a website of your own. We'd be happy to make you a free preview of what a website could look like. Want one? No cost, no obligation. | N9: Open map | O9: Not contacted
A10: 9 | B10: HIGH | C10: No own website | D10: Terry Dobie Hairdressing | E10: barber or hairdresser | F10: Brisbane | G10: Facebook | I10: https://www.facebook.com/Terrydobiehair/ | K10: https://terrydobiehair.wixsite.com/mysite | L10: no real website (uses terrydobiehair.wixsite.com) | M10: Hi Terry Dobie Hairdressing team! [one real detail from their page]. We're AceAds, a web design studio. We noticed that when people in Brisbane search for a hairdresser on Google, they only find your Facebook, not a website of your own. We'd be happy to make you a free preview of what a website could look like. Want one? No cost, no obligation. | N10: Open map | O10: Not contacted
A11: 10 | B11: HIGH | C11: No own website | D11: Nail Today | E11: beauty salon | F11: Brisbane | G11: Facebook | I11: https://www.facebook.com/profile.php?id=100063881476277 | J11: +61 414 266 235 | K11: https://www.facebook.com/profile.php?id=100063881476277 | L11: no real website (uses www.facebook.com) | M11: Hi Nail Today team! [one real detail from their page]. We're AceAds, a web design studio. We noticed that when people in Brisbane search for a beauty salon on Google, they only find your Facebook, not a website of your own. We'd be happy to make you a free preview of what a website could look like. Want one? No cost, no obligation. | N11: Open map | O11: Not contacted
A12: 11 | B12: HIGH | C12: No own website | D12: Canary Lane | E12: boutique | F12: Brisbane | G12: Facebook | I12: https://www.facebook.com/Canary-Lane-686290855153091/ | J12: +61 7 3852 2997 | K12: https://www.facebook.com/Canary-Lane-686290855153091/ | L12: no real website (uses www.facebook.com) | M12: Hi Canary Lane team! [one real detail from their page]. We're AceAds, a web design studio. We noticed that when people in Brisbane search for a boutique on Google, they only find your Facebook, not a website of your own. We'd be happy to make you a free preview of what a website could look like. Want one? No cost, no obligation. | N12: Open map | O12: Not contacted
A13: 12 | B13: HIGH | C13: No own website | D13: Bancroft Roasters, Bardon | E13: cafe | F13: Brisbane | G13: Facebook | I13: https://m.facebook.com/story.php?story_fbid=2013500125499490&id=487145808134937&sfnsn=mo | K13: https://m.facebook.com/story.php?story_fbid=2013500125499490&id=487145808134937&sfnsn=mo | L13: no real website (uses m.facebook.com) | M13: Hi Bancroft Roasters, Bardon team! [one real detail from their page]. We're AceAds, a web design studio. We noticed that when people in Brisbane search for a cafe on Google, they only find your Facebook, not a website of your own. We'd be happy to make you a free preview of what a website could look like. Want one? No cost, no obligation. | N13: Open map | O13: Not contacted
A14: 13 | B14: HIGH | C14: No own website | D14: Bardon Thyme | E14: cafe | F14: Brisbane | G14: Instagram | H14: https://www.instagram.com/bardonthyme/?hl=en | J14: +61 433 022 991 | K14: https://www.instagram.com/bardonthyme/?hl=en | L14: no real website (uses www.instagram.com) | M14: Hi Bardon Thyme team! [one real detail from their page]. We're AceAds, a web design studio. We noticed that when people in Brisbane search for a cafe on Google, they only find your Instagram, not a website of your own. We'd be happy to make you a free preview of what a website could look like. Want one? No cost, no obligation. | N14: Open map | O14: Not contacted
A15: 14 | B15: HIGH | C15: No own website | D15: Canter & Colt | E15: cafe | F15: Brisbane | G15: Facebook | I15: https://www.facebook.com/canterandcolt | J15: +61 7 3289 1087 | K15: https://www.facebook.com/canterandcolt | L15: no real website (uses www.facebook.com) | M15: Hi Canter & Colt team! [one real detail from their page]. We're AceAds, a web design studio. We noticed that when people in Brisbane search for a cafe on Google, they only find your Facebook, not a website of your own. We'd be happy to make you a free preview of what a website could look like. Want one? No cost, no obligation. | N15: Open map | O15: Not contacted
A16: 15 | B16: HIGH | C16: No own website | D16: Coffee Warden | E16: cafe | F16: Brisbane | G16: Facebook | I16: https://www.facebook.com/Coffee-Warden-Sandgate-380818316058328/ | K16: https://www.facebook.com/Coffee-Warden-Sandgate-380818316058328/ | L16: no real website (uses www.facebook.com) | M16: Hi Coffee Warden team! [one real detail from their page]. We're AceAds, a web design studio. We noticed that when people in Brisbane search for a cafe on Google, they only find your Facebook, not a website of your own. We'd be happy to make you a free preview of what a website could look like. Want one? No cost, no obligation. | N16: Open map | O16: Not contacted
A17: 16 | B17: HIGH | C17: No own website | D17: Coffee on the Way | E17: cafe | F17: Brisbane | G17: Facebook | I17: https://www.facebook.com/people/Coffee-on-the-Way/100057414793271/ | J17: +61 407 900 595 | K17: https://www.facebook.com/people/Coffee-on-the-Way/100057414793271/ | L17: no real website (uses www.facebook.com) | M17: Hi Coffee on the Way team! [one real detail from their page]. We're AceAds, a web design studio. We noticed that when people in Brisbane search for a cafe on Google, they only find your Facebook, not a website of your own. We'd be happy to make you a free preview of what a website could look like. Want one? No cost, no obligation. | N17: Open map | O17: Not contacted
A18: 17 | B18: HIGH | C18: No own website | D18: Dropout Espresso | E18: cafe | F18: Brisbane | G18: Facebook | I18: https://www.facebook.com/Dropout-espresso-110045364260266/ | J18: +61 7 3289 5555 | K18: https://www.facebook.com/Dropout-espresso-110045364260266/ | L18: no real website (uses www.facebook.com) | M18: Hi Dropout Espresso team! [one real detail from their page]. We're AceAds, a web design studio. We noticed that when people in Brisbane search for a cafe on Google, they only find your Facebook, not a website of your own. We'd be happy to make you a free preview of what a website could look like. Want one? No cost, no obligation. | N18: Open map | O18: Not contacted
A19: 18 | B19: HIGH | C19: No own website | D19: Fraser's Newstead | E19: cafe | F19: Brisbane | G19: Instagram | H19: https://www.instagram.com/frasersnewstead/ | K19: https://www.instagram.com/frasersnewstead/ | L19: no real website (uses www.instagram.com) | M19: Hi Fraser's Newstead team! [one real detail from their page]. We're AceAds, a web design studio. We noticed that when people in Brisbane search for a cafe on Google, they only find your Instagram, not a website of your own. We'd be happy to make you a free preview of what a website could look like. Want one? No cost, no obligation. | N19: Open map | O19: Not contacted
A20: 19 | B20: HIGH | C20: No own website | D20: Graceville Moments Cafe | E20: cafe | F20: Brisbane | G20: Facebook | I20: https://www.facebook.com/gracevillemoments/ | J20: +61 402 680 192 | K20: https://www.facebook.com/gracevillemoments/ | L20: no real website (uses www.facebook.com) | M20: Hi Graceville Moments Cafe team! [one real detail from their page]. We're AceAds, a web design studio. We noticed that when people in Brisbane search for a cafe on Google, they only find your Facebook, not a website of your own. We'd be happy to make you a free preview of what a website could look like. Want one? No cost, no obligation. | N20: Open map | O20: Not contacted
A21: 20 | B21: HIGH | C21: No own website | D21: Little Red Providore | E21: cafe | F21: Brisbane | G21: Facebook | I21: https://www.facebook.com/littleredprovidore/ | J21: +61 7 3369 4044 | K21: https://www.facebook.com/littleredprovidore/ | L21: no real website (uses www.facebook.com) | M21: Hi Little Red Providore team! [one real detail from their page]. We're AceAds, a web design studio. We noticed that when people in Brisbane search for a cafe on Google, they only find your Facebook, not a website of your own. We'd be happy to make you a free preview of what a website could look like. Want one? No cost, no obligation. | N21: Open map | O21: Not contacted
A22: 21 | B22: HIGH | C22: No own website | D22: Paper Moon Coffee House and Functions | E22: cafe | F22: Brisbane | G22: Facebook | I22: https://www.facebook.com/profile.php?id=61584852192002 | J22: +61 408 135 812 | K22: https://www.facebook.com/profile.php?id=61584852192002 | L22: no real website (uses www.facebook.com) | M22: Hi Paper Moon Coffee House and Functions team! [one real detail from their page]. We're AceAds, a web design studio. We noticed that when people in Brisbane search for a cafe on Google, they only find your Facebook, not a website of your own. We'd be happy to make you a free preview of what a website could look like. Want one? No cost, no obligation. | N22: Open map | O22: Not contacted
A23: 22 | B23: HIGH | C23: No own website | D23: Proud To Serve | E23: cafe | F23: Brisbane | G23: Facebook | I23: https://www.facebook.com/people/PROUD-to-SERVE/100083122461252/ | J23: +61 433 790 454 | K23: https://www.facebook.com/people/PROUD-to-SERVE/100083122461252/ | L23: no real website (uses www.facebook.com) | M23: Hi Proud To Serve team! [one real detail from their page]. We're AceAds, a web design studio. We noticed that when people in Brisbane search for a cafe on Google, they only find your Facebook, not a website of your own. We'd be happy to make you a free preview of what a website could look like. Want one? No cost, no obligation. | N23: Open map | O23: Not contacted
A24: 23 | B24: HIGH | C24: No own website | D24: Remedy Espresso Cafe | E24: cafe | F24: Brisbane | G24: Facebook | I24: https://www.facebook.com/remedyec/ | J24: +61 7 3818 6687 | K24: https://www.facebook.com/remedyec/ | L24: no real website (uses www.facebook.com) | M24: Hi Remedy Espresso Cafe team! [one real detail from their page]. We're AceAds, a web design studio. We noticed that when people in Brisbane search for a cafe on Google, they only find your Facebook, not a website of your own. We'd be happy to make you a free preview of what a website could look like. Want one? No cost, no obligation. | N24: Open map | O24: Not contacted
A25: 24 | B25: HIGH | C25: No own website | D25: Rooka Acai | E25: cafe | F25: Brisbane | G25: Instagram | H25: https://www.instagram.com/rookaacai | J25: +61 435 383 803 | K25: https://www.instagram.com/rookaacai | L25: no real website (uses www.instagram.com) | M25: Hi Rooka Acai team! [one real detail from their page]. We're AceAds, a web design studio. We noticed that when people in Brisbane search for a cafe on Google, they only find your Instagram, not a website of your own. We'd be happy to make you a free preview of what a website could look like. Want one? No cost, no obligation. | N25: Open map | O25: Not contacted
A26: 25 | B26: HIGH | C26: No own website | D26: Story Behind The Coffee | E26: cafe | F26: Brisbane | G26: Facebook | I26: https://www.facebook.com/storybehindthecoffee/ | J26: +61 475 209 660 | K26: https://www.facebook.com/storybehindthecoffee/ | L26: no real website (uses www.facebook.com) | M26: Hi Story Behind The Coffee team! [one real detail from their page]. We're AceAds, a web design studio. We noticed that when people in Brisbane search for a cafe on Google, they only find your Facebook, not a website of your own. We'd be happy to make you a free preview of what a website could look like. Want one? No cost, no obligation. | N26: Open map | O26: Not contacted
A27: 26 | B27: HIGH | C27: No own website | D27: Sundays Cafe | E27: cafe | F27: Brisbane | G27: Facebook | I27: https://www.facebook.com/SundaysCoffeeHouseRocklea/ | J27: +61 7 3150 8771 | K27: https://www.facebook.com/SundaysCoffeeHouseRocklea/ | L27: no real website (uses www.facebook.com) | M27: Hi Sundays Cafe team! [one real detail from their page]. We're AceAds, a web design studio. We noticed that when people in Brisbane search for a cafe on Google, they only find your Facebook, not a website of your own. We'd be happy to make you a free preview of what a website could look like. Want one? No cost, no obligation. | N27: Open map | O27: Not contacted
A28: 27 | B28: HIGH | C28: No own website | D28: The Brass | E28: cafe | F28: Brisbane | G28: Facebook | I28: https://www.facebook.com/profile.php?id=100093799565639 | J28: +61 7 3113 3636 | K28: https://www.facebook.com/profile.php?id=100093799565639 | L28: no real website (uses www.facebook.com) | M28: Hi The Brass team! [one real detail from their page]. We're AceAds, a web design studio. We noticed that when people in Brisbane search for a cafe on Google, they only find your Facebook, not a website of your own. We'd be happy to make you a free preview of what a website could look like. Want one? No cost, no obligation. | N28: Open map | O28: Not contacted
A29: 28 | B29: HIGH | C29: No own website | D29: The Woolshed. | E29: cafe | F29: Brisbane | G29: Instagram | H29: https://www.instagram.com/woolshed.bne/ | K29: https://www.instagram.com/woolshed.bne/ | L29: no real website (uses www.instagram.com) | M29: Hi The Woolshed. team! [one real detail from their page]. We're AceAds, a web design studio. We noticed that when people in Brisbane search for a cafe on Google, they only find your Instagram, not a website of your own. We'd be happy to make you a free preview of what a website could look like. Want one? No cost, no obligation. | N29: Open map | O29: Not contacted
A30: 29 | B30: HIGH | C30: No own website | D30: Vinty Bean | E30: cafe | F30: Brisbane | G30: Instagram | H30: https://www.instagram.com/vintybean/ | K30: https://www.instagram.com/vintybean/ | L30: no real website (uses www.instagram.com) | M30: Hi Vinty Bean team! [one real detail from their page]. We're AceAds, a web design studio. We noticed that when people in Brisbane search for a cafe on Google, they only find your Instagram, not a website of your own. We'd be happy to make you a free preview of what a website could look like. Want one? No cost, no obligation. | N30: Open map | O30: Not contacted
A31: 30 | B31: HIGH | C31: No own website | D31: Dinmore Fruit Barn | E31: deli or specialty food | F31: Brisbane | G31: Facebook | I31: https://www.facebook.com/pages/Dinmore-Fruit-Barn/190399727707208 | J31: +61 7 3282 4221 | K31: https://www.facebook.com/pages/Dinmore-Fruit-Barn/190399727707208 | L31: no real website (uses www.facebook.com) | M31: Hi Dinmore Fruit Barn team! [one real detail from their page]. We're AceAds, a web design studio. We noticed that when people in Brisbane search for a local food store on Google, they only find your Facebook, not a website of your own. We'd be happy to make you a free preview of what a website could look like. Want one? No cost, no obligation. | N31: Open map | O31: Not contacted
A32: 31 | B32: HIGH | C32: No own website | D32: Kadison And Lealta | E32: florist | F32: Brisbane | G32: Facebook | I32: https://www.facebook.com/kadisonandlealta/ | J32: +61 431 454 413 | K32: https://www.facebook.com/kadisonandlealta/ | L32: no real website (uses www.facebook.com) | M32: Hi Kadison And Lealta team! [one real detail from their page]. We're AceAds, a web design studio. We noticed that when people in Brisbane search for a florist on Google, they only find your Facebook, not a website of your own. We'd be happy to make you a free preview of what a website could look like. Want one? No cost, no obligation. | N32: Open map | O32: Not contacted
A33: 32 | B33: HIGH | C33: No own website | D33: Cherished Creations | E33: gift or homewares | F33: Brisbane | G33: Facebook | I33: https://www.facebook.com/cherishedcreationshandmade/ | J33: +61 419 343 235 | K33: https://www.facebook.com/cherishedcreationshandmade/ | L33: no real website (uses www.facebook.com) | M33: Hi Cherished Creations team! [one real detail from their page]. We're AceAds, a web design studio. We noticed that when people in Brisbane search for a gift shop on Google, they only find your Facebook, not a website of your own. We'd be happy to make you a free preview of what a website could look like. Want one? No cost, no obligation. | N33: Open map | O33: Not contacted
A34: 33 | B34: HIGH | C34: No own website | D34: Makers on Main | E34: gift or homewares | F34: Brisbane | G34: Facebook | I34: https://www.facebook.com/Makers-On-Main-281063809243994/ | J34: +61 458 966 151 | K34: https://www.facebook.com/Makers-On-Main-281063809243994/ | L34: no real website (uses www.facebook.com) | M34: Hi Makers on Main team! [one real detail from their page]. We're AceAds, a web design studio. We noticed that when people in Brisbane search for a gift shop on Google, they only find your Facebook, not a website of your own. We'd be happy to make you a free preview of what a website could look like. Want one? No cost, no obligation. | N34: Open map | O34: Not contacted
A35: 34 | B35: HIGH | C35: No own website | D35: Petrie 2nd Hand Furniture | E35: gift or homewares | F35: Brisbane | G35: Facebook | I35: https://www.facebook.com/people/Petrie-secondhand-furniture/100057573274067/ | J35: +61 432 059 374 | K35: https://petrie-secondhand-furniture.business.site/ | L35: no real website (uses petrie-secondhand-furniture.business.site) | M35: Hi Petrie 2nd Hand Furniture team! [one real detail from their page]. We're AceAds, a web design studio. We noticed that when people in Brisbane search for a gift shop on Google, they only find your Facebook, not a website of your own. We'd be happy to make you a free preview of what a website could look like. Want one? No cost, no obligation. | N35: Open map | O35: Not contacted
A36: 35 | B36: HIGH | C36: No own website | D36: Shady Dayz Gifts & Homewares | E36: gift or homewares | F36: Brisbane | G36: Facebook | I36: https://www.facebook.com/shadydayzgifts/ | J36: +61 7 3289 1833 | K36: https://www.facebook.com/shadydayzgifts/ | L36: no real website (uses www.facebook.com) | M36: Hi Shady Dayz Gifts & Homewares team! [one real detail from their page]. We're AceAds, a web design studio. We noticed that when people in Brisbane search for a gift shop on Google, they only find your Facebook, not a website of your own. We'd be happy to make you a free preview of what a website could look like. Want one? No cost, no obligation. | N36: Open map | O36: Not contacted
A37: 36 | B37: HIGH | C37: No own website | D37: Ascot Automotive | E37: mechanic | F37: Brisbane | G37: Facebook | I37: https://www.facebook.com/ascotautomotive4007/ | J37: +61 7 3262 2433 | K37: https://www.facebook.com/ascotautomotive4007/ | L37: no real website (uses www.facebook.com) | M37: Hi Ascot Automotive team! [one real detail from their page]. We're AceAds, a web design studio. We noticed that when people in Brisbane search for a mechanic on Google, they only find your Facebook, not a website of your own. We'd be happy to make you a free preview of what a website could look like. Want one? No cost, no obligation. | N37: Open map | O37: Not contacted
A38: 37 | B38: HIGH | C38: No own website | D38: Next Up Performance & Dyno Tuning | E38: mechanic | F38: Brisbane | G38: Facebook | I38: https://www.facebook.com/next.up.5/ | K38: https://www.facebook.com/next.up.5/ | L38: no real website (uses www.facebook.com) | M38: Hi Next Up Performance & Dyno Tuning team! [one real detail from their page]. We're AceAds, a web design studio. We noticed that when people in Brisbane search for a mechanic on Google, they only find your Facebook, not a website of your own. We'd be happy to make you a free preview of what a website could look like. Want one? No cost, no obligation. | N38: Open map | O38: Not contacted
A39: 38 | B39: HIGH | C39: No own website | D39: Prince Auto & Tyre Service | E39: mechanic | F39: Brisbane | G39: Facebook | I39: https://www.facebook.com/princeauto111/ | J39: +61 402 779 568 | K39: https://www.facebook.com/princeauto111/ | L39: no real website (uses www.facebook.com) | M39: Hi Prince Auto & Tyre Service team! [one real detail from their page]. We're AceAds, a web design studio. We noticed that when people in Brisbane search for a mechanic on Google, they only find your Facebook, not a website of your own. We'd be happy to make you a free preview of what a website could look like. Want one? No cost, no obligation. | N39: Open map | O39: Not contacted
A40: 39 | B40: HIGH | C40: No own website | D40: Shear Designz | E40: pet business | F40: Brisbane | G40: Facebook | I40: https://www.facebook.com/caninestylist.com.au/ | J40: +61 7 3889 0333 | K40: https://www.facebook.com/caninestylist.com.au/ | L40: no real website (uses www.facebook.com) | M40: Hi Shear Designz team! [one real detail from their page]. We're AceAds, a web design studio. We noticed that when people in Brisbane search for a pet shop on Google, they only find your Facebook, not a website of your own. We'd be happy to make you a free preview of what a website could look like. Want one? No cost, no obligation. | N40: Open map | O40: Not contacted
...

Sheet Tracker
A1: Pipeline | B1: Leads
A2: Not contacted | B2: =COUNTIF(Leads!O:O,"Not contacted")
A3: DM sent | B3: =COUNTIF(Leads!O:O,"DM sent")
A4: Replied | B4: =COUNTIF(Leads!O:O,"Replied")
A5: Preview sent | B5: =COUNTIF(Leads!O:O,"Preview sent")
A6: Meeting booked | B6: =COUNTIF(Leads!O:O,"Meeting booked")
A7: Won | B7: =COUNTIF(Leads!O:O,"Won")
A8: Not interested | B8: =COUNTIF(Leads!O:O,"Not interested")
A9: Business closed | B9: =COUNTIF(Leads!O:O,"Business closed")
A11: Reply rate (Replied or later / DMs sent) | B11: =IFERROR((B4+B5+B6+B7+B8)/(B3+B4+B5+B6+B7+B8),0)
A12: Leads per priority
A13: HIGH | B13: =COUNTIF(Leads!B:B,"HIGH")
A14: VERIFY FIRST | B14: =COUNTIF(Leads!B:B,"VERIFY FIRST")
A15: MEDIUM | B15: =COUNTIF(Leads!B:B,"MEDIUM")
A17: Leads per region
A18: Brisbane | B18: =COUNTIF(Leads!F:F,"Brisbane")
A19: Bundaberg | B19: =COUNTIF(Leads!F:F,"Bundaberg")
A20: Cairns | B20: =COUNTIF(Leads!F:F,"Cairns")
A21: Gold Coast | B21: =COUNTIF(Leads!F:F,"Gold Coast")
A22: Ipswich | B22: =COUNTIF(Leads!F:F,"Ipswich")
A23: Logan | B23: =COUNTIF(Leads!F:F,"Logan")
A24: Mackay | B24: =COUNTIF(Leads!F:F,"Mackay")
A25: Moreton Bay | B25: =COUNTIF(Leads!F:F,"Moreton Bay")
A26: Redlands | B26: =COUNTIF(Leads!F:F,"Redlands")
A27: Rockhampton | B27: =COUNTIF(Leads!F:F,"Rockhampton")
A28: Sunshine Coast | B28: =COUNTIF(Leads!F:F,"Sunshine Coast")
A29: Toowoomba | B29: =COUNTIF(Leads!F:F,"Toowoomba")
A30: Townsville | B30: =COUNTIF(Leads!F:F,"Townsville")

Sheet How to work this list
A1: AceAds: Instagram / Facebook outreach, Queensland
A3: Before each DM
A4: 1. Open 'Check on Google Maps'. Skip the business if it is closed or has almost no reviews.
A5: 2. Open their Instagram/Facebook. Replace [one real detail from their page] with something true and specific.
A6: 3. 'VERIFY FIRST' rows: Google the business name first. If they DO have a website, check it on your phone and
A7: rewrite the DM around a problem you can see yourself, or skip them. Never say they have no website unless you checked.
A8: 4. 'Slow to load' was timed from an overseas server. Open the site on your own phone first; if it loads fine, skip that point.
A10: Sending
A11: 5. Send from the AceAds business account, by hand. Max 20 new DMs per account per day.
A12: 6. Never paste the identical message twice in a row. Personalise every one; Meta limits accounts that send copy-paste DMs.
A13: 7. If they reply yes, ask AceAds for their preview (mockups/ in the repo), then send the screenshot and link.
A14: Set Status to 'Preview sent'.
... A24: Source: OpenStreetMap (c) OpenStreetMap contributors, plus links found on the businesses' own websites.
